<?xml version="1.0" encoding="utf-8"?>

<robot name="robot" xmlns:xacro="http://www.ros.org/wiki/xacro">

  <xacro:property name="clearance" value="0.048" />
  <xacro:property name="PI" value="3.14159"/>

  <!-- Matherials -->
  <xacro:include filename="$(find robot_description)/urdf/robot_materials.xacro" />

  <!-- Link base_footprint -->
  <link name="base_footprint">
    <visual>
      <origin xyz="0 0 0" rpy="0 0 0" />
      <geometry>
        <cylinder length="0.001" radius="0.14" />
      </geometry>
      <material name="Clear" />
    </visual>
  </link>

  <!-- Link base_link -->
  <link name="base_link">
    <visual>
      <origin xyz="0 0 0" rpy="0 0 0" />
      <geometry>
        <sphere radius="0.001" />
      </geometry>
    </visual>
  </link>

  <!-- Joint base_footprint base_link -->
  <joint name="base_footprint_to_base_link" type="fixed">
    <origin xyz="0 0 ${clearance}" rpy="0 0 0" />
    <parent link="base_footprint" />
    <child link="base_link" />
  </joint>

  <!-- Link robot_base -->
  <link name="robot_base">
    <inertial>
      <origin xyz="0.0032453 -1.4219E-05 0.008348" rpy="0 0 0" />
      <mass value="3.5" />
      <inertia ixx="0.0093009" ixy="0.0" ixz="0.0" iyy="0.021031" iyz="0.0" izz="0.029655" />
    </inertial>
    <visual>
      <origin xyz="0 0 0" rpy="0 0 0" />
      <geometry>
        <mesh filename="package://robot_description/meshes/Robot_base.STL" scale="0.001 0.001 0.001" />
      </geometry>
      <material name="Base" />
    </visual>
    <collision>
      <origin xyz="0 0 0" rpy="0 0 0" />
      <geometry>
        <mesh filename="package://robot_description/meshes/Robot_base.STL" scale="0.001 0.001 0.001" />
      </geometry>
    </collision>
  </link>

  <!-- Joint robot_base -->
  <joint name="base_link_to_robot_base" type="fixed">
    <origin xyz="0 0 0" rpy="0 0 0" />
    <parent link="base_link" />
    <child link="robot_base" />
  </joint>

  <!-- Link Left_forward_link -->
  <link name="Left_forward_link">
    <inertial>
      <origin xyz="0.00053 0.0 0.0" rpy="0 0 0" />
      <mass value="0.38" />
      <inertia ixx="0.000281" ixy="0.0" ixz="0.0" iyy="0.000159" iyz="0.0" izz="0.000159" />
    </inertial>
    <visual>
      <origin xyz="0 0 0" rpy="0 0 0" />
      <geometry>
        <mesh filename="package://robot_description/meshes/Wheel.STL" scale="0.001 0.001 0.001" />
      </geometry>
      <material name="Wheel" />
    </visual>
    <collision>
      <origin xyz="0 0 0" rpy="0 0 0" />
      <geometry>
        <mesh filename="package://robot_description/meshes/Wheel.STL" scale="0.001 0.001 0.001" />
      </geometry>
    </collision>
  </link>

  <!-- Joint Left_forward_joint -->
  <joint name="Left_forward_joint" type="continuous">
    <origin xyz="0.0634 0.08795 -0.0159" rpy="0 0 1.5708" />
    <parent link="robot_base" />
    <child link="Left_forward_link" />
    <axis xyz="1 0 0" />
  </joint>

  <!-- Link Left_backward_link -->
  <link name="Left_backward_link">
    <inertial>
      <origin xyz="0.00053 0.0 0.0" rpy="0 0 0" />
      <mass value="0.38" />
      <inertia ixx="0.000281" ixy="0.0" ixz="0.0" iyy="0.000159" iyz="0.0" izz="0.000159" />
    </inertial>
    <visual>
      <origin xyz="0 0 0" rpy="0 0 0" />
      <geometry>
        <mesh filename="package://robot_description/meshes/Wheel.STL" scale="0.001 0.001 0.001" />
      </geometry>
      <material name="Wheel" />
    </visual>
    <collision>
      <origin xyz="0 0 0" rpy="0 0 0" />
      <geometry>
        <mesh filename="package://robot_description/meshes/Wheel.STL" scale="0.001 0.001 0.001" />
      </geometry>
    </collision>
  </link>

  <!-- Joint Left_backward_joint -->
  <joint name="Left_backward_joint" type="continuous">
    <origin xyz="-0.0634 0.08795 -0.0159" rpy="0 0 1.5708" />
    <parent link="robot_base" />
    <child link="Left_backward_link" />
    <axis xyz="1 0 0" />
  </joint>

  <!-- Link Right_forward_link -->
  <link name="Right_forward_link">
    <inertial>
      <origin xyz="0.00053 0.0 0.0" rpy="0 0 0" />
      <mass value="0.38" />
      <inertia ixx="0.000281" ixy="0.0" ixz="0.0" iyy="0.000159" iyz="0.0" izz="0.000159" />
    </inertial>
    <visual>
      <origin xyz="0 0 0" rpy="0 0 0" />
      <geometry>
        <mesh filename="package://robot_description/meshes/Wheel.STL" scale="0.001 0.001 0.001" />
      </geometry>
      <material name="Wheel" />
    </visual>
    <collision>
      <origin xyz="0 0 0" rpy="0 0 0" />
      <geometry>
        <mesh filename="package://robot_description/meshes/Wheel.STL" scale="0.001 0.001 0.001" />
      </geometry>
    </collision>
  </link>

  <!-- Joint Right_forward_joint -->
  <joint name="Right_forward_joint" type="continuous">
    <origin xyz="0.0634 -0.08795 -0.0159" rpy="0 0 -1.5707963267949" />
    <parent link="robot_base" />
    <child link="Right_forward_link" />
    <axis xyz="1 0 0" />
  </joint>

  <!-- Link Right_backward_link -->
  <link name="Right_backward_link">
    <inertial>
      <origin xyz="0.00053 0.0 0.0" rpy="0 0 0" />
      <mass value="0.38" />
      <inertia ixx="0.000281" ixy="0.0" ixz="0.0" iyy="0.000159" iyz="0.0" izz="0.000159" />
    </inertial>
    <visual>
      <origin xyz="0 0 0" rpy="0 0 0" />
      <geometry>
        <mesh filename="package://robot_description/meshes/Wheel.STL" scale="0.001 0.001 0.001" />
      </geometry>
      <material name="Wheel" />
    </visual>
    <collision>
      <origin xyz="0 0 0" rpy="0 0 0" />
      <geometry>
        <mesh filename="package://robot_description/meshes/Wheel.STL" scale="0.001 0.001 0.001" />
      </geometry>
    </collision>
  </link>

  <!-- Joint Right_backward_joint -->
  <joint name="Right_backward_joint" type="continuous">
    <origin xyz="-0.0634 -0.08795 -0.0159" rpy="0 0 -1.5708" />
    <parent link="robot_base" />
    <child link="Right_backward_link" />
    <axis xyz="1 0 0" />
  </joint>

  <!-- Link Lidar_Link -->
  <link name="Lidar_Link">
    <inertial>
      <origin xyz="-0.0078 -0.00023 -0.0088" rpy="0 0 0" />
      <mass value="1.0" />
      <inertia ixx="0.000440" ixy="0.0" ixz="-0.0001313" iyy="0.0007248" iyz="0.0" izz="0.0008769" />
    </inertial>
    <visual>
      <origin xyz="0 0 0" rpy="0 0 0" />
      <geometry>
        <mesh filename="package://robot_description/meshes/Lidar.STL" scale="0.001 0.001 0.001" />
      </geometry>
      <material name="Wheel" />
    </visual>
    <collision>
      <origin xyz="0 0 0" rpy="0 0 0" />
      <geometry>
        <mesh filename="package://robot_description/meshes/Lidar.STL" scale="0.001 0.001 0.001" />
      </geometry>
    </collision>
  </link>

  <!-- Joint  -->
  <joint name="Lidar_Joint" type="fixed">
    <origin xyz="0 0 0.1061" rpy="0 0 0" />
    <parent link="robot_base" />
    <child link="Lidar_Link" />
    <axis xyz="0 0 0" />
  </joint>
</robot>